Workbook

Sheet 計画書
A1: テスト計画書
A2: QA自動化ポートフォリオ（SauceDemo／JSONPlaceholder／OWASP Juice Shop）
A4: 文書名 | B4: テスト計画書（QA自動化ポートフォリオ）
A5: 版 | B5: 1.0
A6: 作成日 | B6: 46315
A7: 作成者 | B7: 石井達也
A8: 関連文書 | B8: テスト設計のExcel（要求分析・FV表・テストマップ・テストケース。TC-01〜54）
A9: 黄色のセル | B9: 自分で入力・更新するセル（作成者、予定日、状況、結果、実施日、備考など）。それ以外は、設計Excelから作った内容。
A11: 1. 目的と品質目標
A12: 目的 | B12: QAとして、テスト設計（要求分析 → FV表 → テストマップ → テストケース）から、自動化、CIでの自動実行までを一通り行い、その過程と成果物をポートフォリオとして示す。
A13: 品質目標の考え方 | B13: 品質目標を「あってはならない（Never）／出来なければならない（Must）／あったらいいな（Want）」に分類し、NeverとMustを優先してテストする。詳細は、設計Excelの「要求分析」シート。
A14: 数値の目標（仮置き） | B14: ・通常負荷：10同時ユーザー、立ち上げ10秒、継続1分 ・応答時間：平均1秒以内、95パーセンタイル2秒以内、最大5秒以内 ・エラー率：1%未満 ・限界の目安：エラー率が5%を超える、または応答時間が目標の2倍を超えるとき 公開された仕様はないため、学習用の仮置き。実測して見直す。
A16: 2. テスト対象
A17: UI（機能性） | B17: SauceDemo（https://www.saucedemo.com）。ログイン、ログアウト、商品一覧、カート、チェックアウト。公開されているデモサイト。
A18: API | B18: JSONPlaceholder（https://jsonplaceholder.typicode.com）の /posts。公開されている練習用API。
A19: 負荷（非機能） | B19: OWASP Juice Shop（自分のPC上の http://localhost:3000）。ログイン、商品検索、カート追加。脆弱性を含む練習用アプリなので、外部には公開しない。
A21: 3. テスト範囲
A22: 対象（実施する） | B22: ・機能性：ログイン／ログアウト／商品一覧／カート／チェックアウト（FV-01〜19） ・API：投稿の取得・作成・更新・削除 ・非機能：JMeterで確認できる性能・負荷・耐久・ストレスの一部（NF-01〜10） ・テストケースは全54件（TC-01〜54）。このうち、今回の自動化対象は、UIが11件、JMeterが6件。
A23: 対象外（実施しない） | B23: ・画面の見た目、レイアウト崩れ ・セキュリティ診断（攻撃的な入力による脆弱性の確認） ・使用性、互換性（Chromium以外のブラウザ・端末） ・資源利用性（サーバーのCPU・メモリ。JMeter単体では確認できない） ・性能のチューニングやボトルネックの調査（計測と記録まで） ・第三者のサイトへの負荷テスト
A25: 4. テストの進め方
A26: 設計 | B26: 要求分析（Never/Must/Want）→ FV表 → テストマップ（機能×観点）→ テストケース。仕様書がないため、画面の挙動から要求を推定する。「要確認」の項目は、実施前に手動で確認して、設計Excelに反映する。
A27: 2つの視点 | B27: Checking：仕様どおりに「できること」「できないこと」を確認する（今回、自動化する）。 Testing：誤動作するように条件をぶつけて、バグを叩きに行く（今回は設計のみ。手動で試してから、自動化を判断する）。
A28: 自動化の範囲 | B28: ・UI（pytest/Playwright）：TC-01、TC-02、TC-03、TC-10、TC-15、TC-16、TC-17、TC-18、TC-48、TC-49、TC-50 ・API（Postman/Newman）：6リクエスト（API-01〜06） ・非機能（JMeter）：TC-35、TC-36、TC-37、TC-38、TC-51、TC-54（通常負荷の1本のテストプランで確認する） 上記以外（Testing、段階的負荷・ストレス・耐久・回復確認、TC-05・06の未ログインアクセスなど）は、設計のみ。余裕があれば追加する。自動化の判断の元は、設計ExcelのFV表の「自動化」列。
A29: 実行方法 | B29: ローカルで pytest（UI）、newman（API）、jmeter（非GUI）を実行する。pushのたびに、GitHub ActionsでUIとAPIのテストを自動実行する。
A30: 優先順位 | B30: 1. UIのChecking → 2. CIでの自動実行 → 3. APIテスト → 4. JMeterの通常負荷 → 5. Testingの自動化（余裕があれば）
A32: 5. テスト環境・ツール
A33: 開発PC | B33: Windows。Python 3.12（64bit・推奨）、Git、Node.js、JMeter（Javaが必要）。プロジェクトは、日本語を含まないパス・OneDrive外に置くのが安全。
A34: ブラウザ | B34: Chromium（Playwright）
A35: CI | B35: GitHub Actions（ubuntu-latest）
A36: ツール | B36: Playwright（Python）＋pytest ／ Postman＋Newman ／ JMeter ／ GitHub Actions ／ Git・GitHub
A37: テストデータ | B37: SauceDemoの公開テストユーザー（standard_user、locked_out_user。パスワードは、サイト上に公開されているもの）。JMeterは、ダミーのユーザー（jmeter/data/users.csv）。実在の個人情報は使わない。
A39: 6. 成果物
A40: 設計 | B40: テスト設計のExcel（要求分析、FV表、テストマップ、テストケース）
A41: テストコード | B41: tests/ui/（Playwright）、pages/（Page Object）、tests/api/（Postmanコレクション）、jmeter/（テストプラン。準備中）
A42: 実行結果 | B42: pytestの結果、失敗時のスクリーンショット・トレース（test-results/）、GitHub Actionsの実行結果、JMeterのHTMLレポート
A43: README | B43: 概要、実行方法、設計へのリンク
A44: このExcel | B44: テスト計画書、進捗サマリ、テスト実施記録、スケジュール、リスク、不具合・気づき
A46: 7. 入口基準・終了基準
A47: 入口基準 | B47: ・設計Excel（要求分析・FV表・テストマップ・テストケース）が作成済み ・テスト環境（Python、Playwright、Node.js、Newman）が使える ・実施する項目の「要確認」を、手動で確認済み
A48: 終了基準 | B48: ・自動化対象の項目が、すべて実施されて合格している ・不合格が残る場合は、原因と対応を記録している ・GitHub Actionsが緑になっている ・READMEに、実行方法と結果が書かれている
...

Sheet 進捗サマリ
A1: 進捗サマリ（自動集計）
A2: 「テスト実施記録」シートの「結果」列を更新すると、自動で集計される。
A4: 区分 | B4: 全項目数 | C4: 自動化対象 | D4: 合格 | E4: 不合格 | F4: 保留 | G4: 未実施 | H4: 合格率（自動化対象）
A5: 機能性 | B5: =COUNTIF(テスト実施記録!$B$6:$B$65,A5) -> 41 | C5: =COUNTIFS(テスト実施記録!$B$6:$B$65,A5,テスト実施記録!$I$6:$I$65,"自動化（今回）") -> 11 | D5: =COUNTIFS(テスト実施記録!$B$6:$B$65,A5,テスト実施記録!$I$6:$I$65,"自動化（今回）",テスト実施記録!$K$6:$K$65,"合格") -> 0 | E5: =COUNTIFS(テスト実施記録!$B$6:$B$65,A5,テスト実施記録!$I$6:$I$65,"自動化（今回）",テスト実施記録!$K$6:$K$65,"不合格") -> 0 | F5: =COUNTIFS(テスト実施記録!$B$6:$B$65,A5,テスト実施記録!$I$6:$I$65,"自動化（今回）",テスト実施記録!$K$6:$K$65,"保留") -> 0 | G5: =COUNTIFS(テスト実施記録!$B$6:$B$65,A5,テスト実施記録!$I$6:$I$65,"自動化（今回）",テスト実施記録!$K$6:$K$65,"未実施") -> 11 | H5: =IF(C5=0,0,D5/C5) -> 0
A6: 非機能 | B6: =COUNTIF(テスト実施記録!$B$6:$B$65,A6) -> 13 | C6: =COUNTIFS(テスト実施記録!$B$6:$B$65,A6,テスト実施記録!$I$6:$I$65,"自動化（今回）") -> 6 | D6: =COUNTIFS(テスト実施記録!$B$6:$B$65,A6,テスト実施記録!$I$6:$I$65,"自動化（今回）",テスト実施記録!$K$6:$K$65,"合格") -> 0 | E6: =COUNTIFS(テスト実施記録!$B$6:$B$65,A6,テスト実施記録!$I$6:$I$65,"自動化（今回）",テスト実施記録!$K$6:$K$65,"不合格") -> 0 | F6: =COUNTIFS(テスト実施記録!$B$6:$B$65,A6,テスト実施記録!$I$6:$I$65,"自動化（今回）",テスト実施記録!$K$6:$K$65,"保留") -> 0 | G6: =COUNTIFS(テスト実施記録!$B$6:$B$65,A6,テスト実施記録!$I$6:$I$65,"自動化（今回）",テスト実施記録!$K$6:$K$65,"未実施") -> 6 | H6: =IF(C6=0,0,D6/C6) -> 0
A7: API | B7: =COUNTIF(テスト実施記録!$B$6:$B$65,A7) -> 6 | C7: =COUNTIFS(テスト実施記録!$B$6:$B$65,A7,テスト実施記録!$I$6:$I$65,"自動化（今回）") -> 6 | D7: =COUNTIFS(テスト実施記録!$B$6:$B$65,A7,テスト実施記録!$I$6:$I$65,"自動化（今回）",テスト実施記録!$K$6:$K$65,"合格") -> 0 | E7: =COUNTIFS(テスト実施記録!$B$6:$B$65,A7,テスト実施記録!$I$6:$I$65,"自動化（今回）",テスト実施記録!$K$6:$K$65,"不合格") -> 0 | F7: =COUNTIFS(テスト実施記録!$B$6:$B$65,A7,テスト実施記録!$I$6:$I$65,"自動化（今回）",テスト実施記録!$K$6:$K$65,"保留") -> 0 | G7: =COUNTIFS(テスト実施記録!$B$6:$B$65,A7,テスト実施記録!$I$6:$I$65,"自動化（今回）",テスト実施記録!$K$6:$K$65,"未実施") -> 6 | H7: =IF(C7=0,0,D7/C7) -> 0
A8: 合計 | B8: =SUM(B5:B7) -> 60 | C8: =SUM(C5:C7) -> 23 | D8: =SUM(D5:D7) -> 0 | E8: =SUM(E5:E7) -> 0 | F8: =SUM(F5:F7) -> 0 | G8: =SUM(G5:G7) -> 23 | H8: =IF(C8=0,0,D8/C8) -> 0
A10: 重要度 | B10: 全項目数 | C10: 自動化対象 | D10: 合格 | E10: 不合格 | F10: 保留 | G10: 未実施 | H10: 合格率（自動化対象）
A11: A | B11: =COUNTIF(テスト実施記録!$F$6:$F$65,A11) -> 26 | C11: =COUNTIFS(テスト実施記録!$F$6:$F$65,A11,テスト実施記録!$I$6:$I$65,"自動化（今回）") -> 17 | D11: =COUNTIFS(テスト実施記録!$F$6:$F$65,A11,テスト実施記録!$I$6:$I$65,"自動化（今回）",テスト実施記録!$K$6:$K$65,"合格") -> 0 | E11: =COUNTIFS(テスト実施記録!$F$6:$F$65,A11,テスト実施記録!$I$6:$I$65,"自動化（今回）",テスト実施記録!$K$6:$K$65,"不合格") -> 0 | F11: =COUNTIFS(テスト実施記録!$F$6:$F$65,A11,テスト実施記録!$I$6:$I$65,"自動化（今回）",テスト実施記録!$K$6:$K$65,"保留") -> 0 | G11: =COUNTIFS(テスト実施記録!$F$6:$F$65,A11,テスト実施記録!$I$6:$I$65,"自動化（今回）",テスト実施記録!$K$6:$K$65,"未実施") -> 17 | H11: =IF(C11=0,0,D11/C11) -> 0
A12: B | B12: =COUNTIF(テスト実施記録!$F$6:$F$65,A12) -> 20 | C12: =COUNTIFS(テスト実施記録!$F$6:$F$65,A12,テスト実施記録!$I$6:$I$65,"自動化（今回）") -> 0 | D12: =COUNTIFS(テスト実施記録!$F$6:$F$65,A12,テスト実施記録!$I$6:$I$65,"自動化（今回）",テスト実施記録!$K$6:$K$65,"合格") -> 0 | E12: =COUNTIFS(テスト実施記録!$F$6:$F$65,A12,テスト実施記録!$I$6:$I$65,"自動化（今回）",テスト実施記録!$K$6:$K$65,"不合格") -> 0 | F12: =COUNTIFS(テスト実施記録!$F$6:$F$65,A12,テスト実施記録!$I$6:$I$65,"自動化（今回）",テスト実施記録!$K$6:$K$65,"保留") -> 0 | G12: =COUNTIFS(テスト実施記録!$F$6:$F$65,A12,テスト実施記録!$I$6:$I$65,"自動化（今回）",テスト実施記録!$K$6:$K$65,"未実施") -> 0 | H12: =IF(C12=0,0,D12/C12) -> 0
A13: C | B13: =COUNTIF(テスト実施記録!$F$6:$F$65,A13) -> 8 | C13: =COUNTIFS(テスト実施記録!$F$6:$F$65,A13,テスト実施記録!$I$6:$I$65,"自動化（今回）") -> 0 | D13: =COUNTIFS(テスト実施記録!$F$6:$F$65,A13,テスト実施記録!$I$6:$I$65,"自動化（今回）",テスト実施記録!$K$6:$K$65,"合格") -> 0 | E13: =COUNTIFS(テスト実施記録!$F$6:$F$65,A13,テスト実施記録!$I$6:$I$65,"自動化（今回）",テスト実施記録!$K$6:$K$65,"不合格") -> 0 | F13: =COUNTIFS(テスト実施記録!$F$6:$F$65,A13,テスト実施記録!$I$6:$I$65,"自動化（今回）",テスト実施記録!$K$6:$K$65,"保留") -> 0 | G13: =COUNTIFS(テスト実施記録!$F$6:$F$65,A13,テスト実施記録!$I$6:$I$65,"自動化（今回）",テスト実施記録!$K$6:$K$65,"未実施") -> 0 | H13: =IF(C13=0,0,D13/C13) -> 0
A14: －（API） | B14: =COUNTIF(テスト実施記録!$F$6:$F$65,"－") -> 6 | C14: =COUNTIFS(テスト実施記録!$F$6:$F$65,"－",テスト実施記録!$I$6:$I$65,"自動化（今回）") -> 6 | D14: =COUNTIFS(テスト実施記録!$F$6:$F$65,"－",テスト実施記録!$I$6:$I$65,"自動化（今回）",テスト実施記録!$K$6:$K$65,"合格") -> 0 | E14: =COUNTIFS(テスト実施記録!$F$6:$F$65,"－",テスト実施記録!$I$6:$I$65,"自動化（今回）",テスト実施記録!$K$6:$K$65,"不合格") -> 0 | F14: =COUNTIFS(テスト実施記録!$F$6:$F$65,"－",テスト実施記録!$I$6:$I$65,"自動化（今回）",テスト実施記録!$K$6:$K$65,"保留") -> 0 | G14: =COUNTIFS(テスト実施記録!$F$6:$F$65,"－",テスト実施記録!$I$6:$I$65,"自動化（今回）",テスト実施記録!$K$6:$K$65,"未実施") -> 6 | H14: =IF(C14=0,0,D14/C14) -> 0
A16: 終了基準の判定（自動化対象がすべて合格） | B16: =IF(AND(C8>0,D8=C8),"達成","未達") -> 未達
A18: 補足
A19: ・終了基準の全体は、「計画書」の「7. 入口基準・終了基準」を参照（GitHub Actionsが緑、READMEの記載なども含む）。
A20: ・「保留」は、自動化対象だが、今回は見送った項目に使う。保留が残っている間は、「未達」になる。
A21: ・設計のみの項目（Testingなど）は、実施対象に含めない。

Sheet テスト実施記録
A1: テスト実施記録
A2: 設計Excelのテストケース（TC-01〜）と、APIテスト（API-01〜06）の一覧。「実施区分」が「自動化（今回）」のものが、今回の実施対象。「結果」「実施日」「備考」は、黄色のセルに入力する。
A3: 実施区分は、設計ExcelのFV表の「自動化」列から決めた。テスト手順・期待結果は、設計Excelのテストケースシートを参照。
A5: No | B5: 区分 | C5: テストID | D5: 機能 | E5: 観点 | F5: 重要度 | G5: テスト内容 | H5: 元FV/NF | I5: 実施区分 | J5: ツール | K5: 結果 | L5: 実施日 | M5: 備考
A6: 1 | B6: 機能性 | C6: TC-01 | D6: ログイン | E6: 基本動作 | F6: A | G6: 正しいユーザー名＋パスワードでログインできる | H6: FV-09 | I6: 自動化（今回） | J6: pytest / Playwright | K6: 未実施
A7: 2 | B7: 機能性 | C7: TC-02 | D7: ログイン | E7: エラー表示 | F7: A | G7: 誤ったパスワードでログインできない | H7: FV-01 | I7: 自動化（今回） | J7: pytest / Playwright | K7: 未実施
A8: 3 | B8: 機能性 | C8: TC-03 | D8: ログイン | E8: エラー表示 | F8: A | G8: ロックされたユーザーでログインできない | H8: FV-02 | I8: 自動化（今回） | J8: pytest / Playwright | K8: 未実施
A9: 4 | B9: 機能性 | C9: TC-04 | D9: ログイン | E9: 画面遷移 | F9: A | G9: ログイン後に商品一覧へ遷移する | H9: FV-09 | I9: 設計のみ | J9: － | K9: －
A10: 5 | B10: 機能性 | C10: TC-05 | D10: 未ログインアクセス | E10: URL直接 | F10: A | G10: 未ログインで商品一覧へアクセス | H10: FV-04 | I10: 設計のみ | J10: － | K10: － | M10: 次フェーズ
A11: 6 | B11: 機能性 | C11: TC-06 | D11: 未ログインアクセス | E11: URL直接 | F11: A | G11: 未ログインでカート・購入画面へアクセス | H11: FV-04 | I11: 設計のみ | J11: － | K11: － | M11: 次フェーズ
A12: 7 | B12: 機能性 | C12: TC-07 | D12: 購入（名） | E12: 入力値 | F12: B | G12: 名が未入力の場合、購入不可 | H12: FV-05 | I12: 設計のみ | J12: － | K12: －
A13: 8 | B13: 機能性 | C13: TC-08 | D13: 購入（姓） | E13: 入力値 | F13: B | G13: 姓が未入力の場合、購入不可 | H13: FV-06 | I13: 設計のみ | J13: － | K13: －
A14: 9 | B14: 機能性 | C14: TC-09 | D14: 購入（郵便番号） | E14: 入力値 | F14: B | G14: 郵便番号が未入力の場合、購入不可 | H14: FV-07 | I14: 設計のみ | J14: － | K14: －
A15: 10 | B15: 機能性 | C15: TC-10 | D15: 購入 | E15: 基本動作 | F15: A | G15: 購入が完了する | H15: FV-16 | I15: 自動化（今回） | J15: pytest / Playwright | K15: 未実施
A16: 11 | B16: 機能性 | C16: TC-11 | D16: 購入 | E16: 状態保持 | F16: B | G16: 購入後カートが空になる | H16: FV-16 | I16: 設計のみ | J16: － | K16: －
A17: 12 | B17: 機能性 | C17: TC-12 | D17: 金額表示 | E17: 表示内容 | F17: A | G17: 小計が正しい | H17: FV-08 | I17: 設計のみ | J17: － | K17: －
A18: 13 | B18: 機能性 | C18: TC-13 | D18: 金額表示 | E18: 表示内容 | F18: A | G18: 税額が正しい | H18: FV-08 | I18: 設計のみ | J18: － | K18: －
A19: 14 | B19: 機能性 | C19: TC-14 | D19: 金額表示 | E19: 表示内容 | F19: A | G19: 合計が正しい | H19: FV-08 | I19: 設計のみ | J19: － | K19: －
A20: 15 | B20: 機能性 | C20: TC-15 | D20: 商品一覧 | E20: 表示内容 | F20: A | G20: 商品一覧が正しく表示される | H20: FV-13 | I20: 自動化（今回） | J20: pytest / Playwright | K20: 未実施
A21: 16 | B21: 機能性 | C21: TC-16 | D21: 商品一覧 | E21: 表示内容 | F21: A | G21: 商品名・価格・追加ボタンが表示される | H21: FV-13 | I21: 自動化（今回） | J21: pytest / Playwright | K21: 未実施
A22: 17 | B22: 機能性 | C22: TC-17 | D22: カート追加 | E22: 基本動作 | F22: A | G22: 商品追加でバッジ件数が増える | H22: FV-14 | I22: 自動化（今回） | J22: pytest / Playwright | K22: 未実施
A23: 18 | B23: 機能性 | C23: TC-18 | D23: カート追加 | E23: 表示内容 | F23: A | G23: 追加後ボタンがRemoveに変わる | H23: FV-14 | I23: 自動化（今回） | J23: pytest / Playwright | K23: 未実施
... A27: 22 | B27: 機能性 | C27: TC-22 | D27: ログイン | E27: 状態保持 | F27: B | G27: ログイン失敗後に成功する | H27: FV-09 | I27: 設計のみ | J27: － | K27: －
A28: 23 | B28: 機能性 | C28: TC-23 | D28: ログイン | E28: 状態保持 | F28: B | G28: ログアウト後に再ログインできる | H28: FV-12 | I28: 設計のみ | J28: － | K28: － | M28: 将来
A29: 24 | B29: 機能性 | C29: TC-24 | D29: ログイン | E29: 状態保持 | F29: B | G29: ログイン後に更新しても状態保持 | H29: FV-09 | I29: 設計のみ | J29: － | K29: －
A30: 25 | B30: 機能性 | C30: TC-25 | D30: 商品一覧 | E30: 画面遷移 | F30: B | G30: 商品詳細から戻っても一覧が正しい | H30: FV-13 | I30: 設計のみ | J30: － | K30: －
A31: 26 | B31: 機能性 | C31: TC-26 | D31: 商品一覧 | E31: 繰り返し | F31: B | G31: ページ更新しても表示が崩れない | H31: FV-13 | I31: 設計のみ | J31: － | K31: －
A32: 27 | B32: 機能性 | C32: TC-27 | D32: カート追加 | E32: 繰り返し | F32: B | G32: 同じ商品を連続追加しても件数が正しい | H32: FV-14 | I32: 設計のみ | J32: － | K32: －
A33: 28 | B33: 機能性 | C33: TC-28 | D33: カート削除 | E33: 組み合わせ | F33: B | G33: 追加→削除を繰り返しても件数が正しい | H33: FV-15 | I33: 設計のみ | J33: － | K33: －
A34: 29 | B34: 機能性 | C34: TC-29 | D34: 購入取消し | E34: 画面遷移 | F34: B | G34: 取消しでカートに戻る | H34: FV-17 | I34: 設計のみ | J34: － | K34: －
A35: 30 | B35: 機能性 | C35: TC-30 | D35: 購入取消し | E35: 状態保持 | F35: B | G35: 取消し後もカートが保持される | H35: FV-17 | I35: 設計のみ | J35: － | K35: －
A36: 31 | B36: 機能性 | C36: TC-31 | D36: 並び替え | E36: 表示内容 | F36: B | G36: 名前昇順・降順で並び替わる | H36: FV-18 | I36: 設計のみ | J36: － | K36: － | M36: 将来
A37: 32 | B37: 機能性 | C37: TC-32 | D37: 並び替え | E37: 表示内容 | F37: B | G37: 価格昇順・降順で並び替わる | H37: FV-18 | I37: 設計のみ | J37: － | K37: － | M37: 将来
A38: 33 | B38: 機能性 | C38: TC-33 | D38: 商品詳細 | E38: 画面遷移 | F38: B | G38: 商品名クリックで詳細画面へ遷移 | H38: FV-19 | I38: 設計のみ | J38: － | K38: － | M38: 将来
A39: 34 | B39: 機能性 | C39: TC-34 | D39: 商品詳細 | E39: 表示内容 | F39: B | G39: 詳細画面に情報が表示される | H39: FV-19 | I39: 設計のみ | J39: － | K39: － | M39: 将来
A40: 35 | B40: 非機能 | C40: TC-35 | D40: 性能 | E40: NF | F40: A | G40: ログイン応答時間が閾値内 | H40: NF-01 | I40: 自動化（今回） | J40: JMeter | K40: 未実施
A41: 36 | B41: 非機能 | C41: TC-36 | D41: 性能 | E41: NF | F41: A | G41: 商品一覧応答時間が閾値内 | H41: NF-06 | I41: 自動化（今回） | J41: JMeter | K41: 未実施
A42: 37 | B42: 非機能 | C42: TC-37 | D42: 性能 | E42: NF | F42: A | G42: カート追加応答時間が閾値内 | H42: NF-07 | I42: 自動化（今回） | J42: JMeter | K42: 未実施
A43: 38 | B43: 非機能 | C43: TC-38 | D43: 負荷 | E43: NF | F43: A | G43: 10ユーザー同時利用でエラーなく完了 | H43: NF-08 | I43: 自動化（今回） | J43: JMeter | K43: 未実施
A44: 39 | B44: 非機能 | C44: TC-39 | D44: ストレス | E44: NF | F44: A | G44: 限界人数で応答時間・エラー率が閾値超過 | H44: NF-10 | I44: 設計のみ | J44: － | K44: －
...

Sheet スケジュール
A1: スケジュール
A2: 予定開始・予定終了・状況・備考は、黄色のセルに入力する（日付の例：2026-10-20）。日数は、自動で計算される。
A4: No | B4: 工程 | C4: 作業内容 | D4: 成果物 | E4: 予定開始 | F4: 予定終了 | G4: 日数 | H4: 状況 | I4: 備考
A5: 1 | B5: テスト設計 | C5: 要求分析、FV表、テストマップ、テストケース（TC-01〜54）を書く | D5: 設計Excel | G5: =IF(AND(E5<>"",F5<>""),F5-E5+1,"") | H5: 完了
A6: 2 | B6: 環境構築 | C6: Python 3.12、Playwright、Git、GitHubの認証を整える | D6: 動く開発環境 | G6: =IF(AND(E6<>"",F6<>""),F6-E6+1,"") | H6: 未着手
A7: 3 | B7: 要確認項目の手動確認 | C7: エラー文言、遷移先、金額が出る画面・税率などを実画面で確認し、設計Excelの期待結果を確定する | D7: 更新した設計Excel | G7: =IF(AND(E7<>"",F7<>""),F7-E7+1,"") | H7: 未着手
A8: 4 | B8: コードと設計の番号合わせ | C8: pytestのテスト名・docstringと、READMEの「TC-01〜06」を、設計ExcelのTC番号に合わせる | D8: tests/ui/、README.md | G8: =IF(AND(E8<>"",F8<>""),F8-E8+1,"") | H8: 未着手
A9: 5 | B9: UIテストの実装（Checking） | C9: TC-01、TC-02、TC-03、TC-10、TC-15、TC-16、TC-17、TC-18、TC-48、TC-49、TC-50（11件）を実装して、すべて通す | D9: tests/ui/、pages/ | G9: =IF(AND(E9<>"",F9<>""),F9-E9+1,"") | H9: 未着手
A10: 6 | B10: 失敗時のレポート確認 | C10: 失敗したときに、スクリーンショット・トレースが残ることを確認する | D10: pytest.ini | G10: =IF(AND(E10<>"",F10<>""),F10-E10+1,"") | H10: 未着手
A11: 7 | B11: APIテスト | C11: Postmanでコレクションを作り、Newmanで実行する | D11: tests/api/ | G11: =IF(AND(E11<>"",F11<>""),F11-E11+1,"") | H11: 未着手
A12: 8 | B12: CI（GitHub Actions） | C12: pushのたびに、UIテストとAPIテストを自動実行する | D12: .github/workflows/test.yml | G12: =IF(AND(E12<>"",F12<>""),F12-E12+1,"") | H12: 未着手
A13: 9 | B13: JMeter（通常負荷） | C13: Juice Shopを起動し、リクエストを確認して、TC-35、TC-36、TC-37、TC-38、TC-51、TC-54を確認するテストプランを作成・実行する | D13: jmeter/load-test.jmx、HTMLレポート | G13: =IF(AND(E13<>"",F13<>""),F13-E13+1,"") | H13: 未着手
A14: 10 | B14: Testingの追加自動化（任意） | C14: 入力違いをparametrizeで追加し、手順違いを別のテストで追加する | D14: 追加したテスト | G14: =IF(AND(E14<>"",F14<>""),F14-E14+1,"") | H14: 未着手
A15: 11 | B15: README・経歴書への反映 | C15: READMEを仕上げ、実行結果を載せる。経歴書にGitHubのURLを追記する | D15: README.md、経歴書 | G15: =IF(AND(E15<>"",F15<>""),F15-E15+1,"") | H15: 未着手

Sheet リスク
A1: リスクと対策
A2: 状況は、黄色のセルで更新する。
A4: No | B4: リスク | C4: 影響度 | D4: 発生可能性 | E4: 対策 | F4: 状況
A5: 1 | B5: 設計ExcelのTC番号と、pytestコード・READMEの番号（旧TC-01〜06）が別物になっている | C5: 中 | D5: 高 | E5: 実装前に、テスト名・docstringを設計ExcelのTC番号に合わせる。READMEの「TC-01〜06」も直す。 | F5: 未対応
A6: 2 | B6: エラー文言・税率などの期待結果が、実画面と違う（未確認の推定） | C6: 高 | D6: 高 | E6: 実施前に手動で確認し、設計Excelの期待結果を確定する。エラー文言は部分一致で確認する。 | F6: 未対応
A7: 3 | B7: 仕様書がなく、期待結果（エラー文言、遷移先など）が推定のため、実際の画面と違う | C7: 高 | D7: 高 | E7: 実施前に、「要確認」の項目を手動で確認して、設計書に反映する。エラー文言は、部分一致で確認する。 | F7: 未対応
A8: 4 | B8: 第三者のサイト（SauceDemo、JSONPlaceholder）の変更で、テストが壊れる | C8: 中 | D8: 中 | E8: data-test属性でロケーターを指定する。Page Objectでロケーターを1か所に集める。失敗時のスクリーンショット・トレースで、原因をすぐ確認する。 | F8: 未対応
A9: 5 | B9: 第三者のサイトの停止・遅延で、CIが落ちる | C9: 中 | D9: 低 | E9: 失敗した場合は、サイトの状態を確認して再実行する。実行結果は、テストの失敗か、環境の問題かを分けて記録する。 | F9: 未対応
A10: 6 | B10: 環境構築でつまずく（古いPython、日本語のパス、OneDrive、Gitの認証） | C10: 中 | D10: 高 | E10: Python 3.12（64bit）を使う。プロジェクトは、日本語を含まないパス・OneDrive外に置く。Gitを最新にして、ブラウザで認証する。 | F10: 未対応
A11: 7 | B11: Juice Shopのエンドポイントやパラメータが、バージョンで変わる | C11: 中 | D11: 中 | E11: ブラウザの開発者ツール（Networkタブ）で、実際のリクエストを確認してから作る。使ったバージョンをREADMEに記録する。 | F11: 未対応
A12: 8 | B12: 負荷テストの結果が、自分のPCの性能に左右される | C12: 中 | D12: 高 | E12: 小さい負荷から始める。目標値は想定値とし、実測して見直す。結果は、参考値として扱う。 | F12: 未対応
A13: 9 | B13: 脆弱性を含むJuice Shopを、誤って外部に公開してしまう | C13: 高 | D13: 低 | E13: localhostでのみ動かす。他人のサイトや公開サイトには、負荷をかけない。 | F13: 未対応
A14: 10 | B14: 時間が足りず、範囲が広がりすぎる | C14: 中 | D14: 高 | E14: 優先順位（Checkingの自動化 → CI → API → JMeter → Testing）で進める。Testingは設計のみとし、余裕があれば追加する。 | F14: 未対応
A15: 11 | B15: アクセストークンなどの秘密情報を、誤ってコミットする | C15: 高 | D15: 低 | E15: .envを.gitignoreに入れる。トークンはファイルやREADMEに書かない。コミット前に、git statusで確認する。 | F15: 未対応

Sheet 不具合・気づき
A1: 不具合・気づき
A2: テスト中に見つけた「仕様の推定と違う挙動」や不具合を記録する。黄色のセルに入力する。1行目は記入例なので、消して使う。
A4: No | B4: 発見日 | C4: 関連（FV / TC） | D4: 内容 | E4: 再現手順 | F4: 期待していた結果 | G4: 実際の結果 | H4: 対応方針 | I4: 状態
A5: （記入例） | B5: 46315 | C5: FV-07-T | D5: 郵便番号欄に英字を入れても、次の画面に進める | E5: 1. 商品をカートに入れてチェックアウトへ 2. 郵便番号に「abc」を入力して Continue を押す | F5: 形式のエラーが表示される（推定） | G5: エラーが出ず、確認画面に進んだ | H5: 設計書を修正 | I5: 対応済み
